Traceback (most recent call last):
  File "/Users/yerassyl/.pyenv/versions/3.10.13/lib/python3.10/site-packages/jupyter_cache/executors/utils.py", line 58, in single_nb_execution
    executenb(
  File "/Users/yerassyl/.pyenv/versions/3.10.13/lib/python3.10/site-packages/nbclient/client.py", line 1305, in execute
    return NotebookClient(nb=nb, resources=resources, km=km, **kwargs).execute()
  File "/Users/yerassyl/.pyenv/versions/3.10.13/lib/python3.10/site-packages/jupyter_core/utils/__init__.py", line 173, in wrapped
    return loop.run_until_complete(inner)
  File "/Users/yerassyl/.pyenv/versions/3.10.13/lib/python3.10/asyncio/base_events.py", line 649, in run_until_complete
    return future.result()
  File "/Users/yerassyl/.pyenv/versions/3.10.13/lib/python3.10/site-packages/nbclient/client.py", line 705, in async_execute
    await self.async_execute_cell(
  File "/Users/yerassyl/.pyenv/versions/3.10.13/lib/python3.10/site-packages/nbclient/client.py", line 1058, in async_execute_cell
    await self._check_raise_for_error(cell, cell_index, exec_reply)
  File "/Users/yerassyl/.pyenv/versions/3.10.13/lib/python3.10/site-packages/nbclient/client.py", line 914, in _check_raise_for_error
    raise CellExecutionError.from_cell_and_msg(cell, exec_reply_content)
nbclient.exceptions.CellExecutionError: An error occurred while executing the following cell:
------------------
# The estimated coefficients will all be around 1:
#print(log_reg.coef_)

# Those values, however, will show that the second parameter
# is more influential
l = list(np.std(X_test, 0)*log_reg.coef_[0])

l = [abs(val) for val in l]
l

cols = list(df.columns[:-1])
cols

df = pd.DataFrame.from_dict({'features': cols,
                   'coefs': l})
df
mean perimeter
mean area
------------------


[0;36m  Cell [0;32mIn[4], line 17[0;36m[0m
[0;31m    mean perimeter[0m
[0m         ^[0m
[0;31mSyntaxError[0m[0;31m:[0m invalid syntax


